
Execution failed. User process 'python' exited with status code 1. Please check log file 'user_logs/std_log.txt' for error details. Error: Traceback (most recent call last):
  File "step3_inference_run.py", line 153, in <module>
    main(args.input_path, args.final_output_dir)
TypeError: main() missing 2 required positional arguments: 'key_output_dir' and 'final_output_dir'
