[DEBUG] TRU:Check if PC-008694 is present in data ingestion step
                   mat_num      mat_num_padded    mat_num_original RGN_CD   
279625  000000000510006535  000000000510006535  000000000510006535    NaN  \

             FG_NM                                         FG_SPEC_NM FD_NM   
279625  FG-0048803  510006535 Desitin Maximum Strength Paste 40% Z...  None  \

         CHILD_NM CHILD_NM_original   
279625  PC-008694         PC-008694  \

                                         CHILD_TITLE_DESC spec_type_inferred   
279625  Shipper - 376  x 281 x 84 mm - RSC - 32 ECT Fl...                 PC  \

               TEMPL_TYPE_CD        CHILD_TYPE_CD   
279625  Corrugated / Shipper  Packaging Component  \

                           ERP_DESC                         SPEC_FLOW_CD   
279625  DESITIN MS OINTMENT JAR 16Z  FG-0048803 > DC-0079931 > PC-008694  \

       TRD_NM_CONCAT TRD_NM_FULL                       key_tru  
279625           NaN         NaN  000000000510006535_PC-008694  
Cleaning up all outstanding Run operations, waiting 300.0 seconds
1 items cleaning up...
Cleanup took 0.08907842636108398 seconds
Traceback (most recent call last):
  File "/opt/conda/envs/ptca/lib/python3.8/site-packages/pandas/core/indexes/base.py", line 3652, in get_loc
    return self._engine.get_loc(casted_key)
  File "pandas/_libs/index.pyx", line 147, in pandas._libs.index.IndexEngine.get_loc
  File "pandas/_libs/index.pyx", line 176, in pandas._libs.index.IndexEngine.get_loc
  File "pandas/_libs/hashtable_class_helper.pxi", line 7080, in pandas._libs.hashtable.PyObjectHashTable.get_item
  File "pandas/_libs/hashtable_class_helper.pxi", line 7088, in pandas._libs.hashtable.PyObjectHashTable.get_item
KeyError: 'key_tru'

The above exception was the direct cause of the following exception:

Traceback (most recent call last):
  File "cross_hound/matcher.py", line 1487, in <module>
    main(input_dir=args.get('input_dir'),
  File "cross_hound/matcher.py", line 1303, in main
    erp, tru, erp_discarded, tru_discarded, run_params, tru_no_erp,tru_off_specs_no_common, bundles = ingest_data_and_prepare_examples(
  File "/mnt/azureml/cr/j/0c5a0ec080ae4c189771d43ac8296765/exe/wd/cross_hound/data_ingestion.py", line 605, in ingest_data_and_prepare_examples
    erp_discarded['key_prediction'] = erp_discarded['key_erp'] + '_' + erp_discarded['key_tru']
  File "/opt/conda/envs/ptca/lib/python3.8/site-packages/pandas/core/frame.py", line 3760, in __getitem__
    indexer = self.columns.get_loc(key)
  File "/opt/conda/envs/ptca/lib/python3.8/site-packages/pandas/core/indexes/base.py", line 3654, in get_loc
    raise KeyError(key) from err
KeyError: 'key_tru'
