
î¨¹
Execution failed. User process 'python' exited with status code 1. Please check log file 'user_logs/std_log.txt' for error details. Error:     dataflow = _transform_and_validate(
  File "/opt/conda/envs/ptca/lib/python3.8/site-packages/azureml/data/dataset_factory.py", line 1173, in _transform_and_validate
    _validate_has_data(dataflow, 'Failed to validate the data.')
  File "/opt/conda/envs/ptca/lib/python3.8/site-packages/azureml/data/dataset_error_handling.py", line 69, in _validate_has_data
    raise DatasetValidationError(error_message + '\n' + e.compliant_message, exception=e)
azureml.data.dataset_error_handling.DatasetValidationError: DatasetValidationError:
	Message: Failed to validate the data.
ScriptExecutionException was caused by StreamAccessException.
  StreamAccessException was caused by NotFoundException.
    Found no resources for the input provided: '[REDACTED]'
| session_id=1b459d42-da98-43f9-8a5a-7630036c1d48
	InnerException None
	ErrorResponse 
{
    "error": {
        "code": "UserError",
        "message": "Failed to validate the data.\nScriptExecutionException was caused by StreamAccessException.\n  StreamAccessException was caused by NotFoundException.\n    Found no resources for the input provided: '[REDACTED]'\n| session_id=1b459d42-da98-43f9-8a5a-7630036c1d48"
    }
}


