Execution failed. User process 'python' exited with status code 1. Please check log file 'user_logs/std_log.txt' for error details. Error: Traceback (most recent call last):
  File "step_1a_direct_mapping.py", line 185, in <module>
    main()
  File "step_1a_direct_mapping.py", line 158, in main
    df, mapping_df = load_data(args.input_path, args.mapping_csv)
  File "step_1a_direct_mapping.py", line 21, in load_data
    mapping_df = pd.read_csv(mapping_csv)
  File "/opt/conda/envs/ptca/lib/python3.8/site-packages/pandas/io/parsers/readers.py", line 912, in read_csv
    return _read(filepath_or_buffer, kwds)
  File "/opt/conda/envs/ptca/lib/python3.8/site-packages/pandas/io/parsers/readers.py", line 577, in _read
    parser = TextFileReader(filepath_or_buffer, **kwds)
  File "/opt/conda/envs/ptca/lib/python3.8/site-packages/pandas/io/parsers/readers.py", line 1407, in __init__
    self._engine = self._make_engine(f, self.engine)
  File "/opt/conda/envs/ptca/lib/python3.8/site-packages/pandas/io/parsers/readers.py", line 1661, in _make_engine
    self.handles = get_handle(
  File "/opt/conda/envs/ptca/lib/python3.8/site-packages/pandas/io/common.py", line 859, in get_handle
    handle = open(
IsADirectoryError: [Errno 21] Is a directory: '/mnt/azureml/cr/j/28adfffc042d450d8f289af2e541d10d/cap/data-capability/wd/INPUT_high_conf_map'


