Traceback (most recent call last):
  File "step_5_run_inference.py", line 134, in <module>
    main(args.input_path)
  File "step_5_run_inference.py", line 108, in main
    length_scaled = sub_scaler.transform(subset[['CMPNT_MATL_DESC_LEN']])
  File "/opt/conda/envs/ptca/lib/python3.8/site-packages/pandas/core/frame.py", line 3766, in __getitem__
    indexer = self.columns._get_indexer_strict(key, "columns")[1]
  File "/opt/conda/envs/ptca/lib/python3.8/site-packages/pandas/core/indexes/base.py", line 5876, in _get_indexer_strict
    self._raise_if_missing(keyarr, indexer, axis_name)
  File "/opt/conda/envs/ptca/lib/python3.8/site-packages/pandas/core/indexes/base.py", line 5935, in _raise_if_missing
    raise KeyError(f"None of [{key}] are in the [{axis_name}]")
KeyError: "None of [Index(['CMPNT_MATL_DESC_LEN'], dtype='object')] are in the [columns]"
